Workbook
Name Slicer_Payment_Mode: #N/A
Name Slicer_Product_Category: #N/A
Name Slicer_Region: #N/A
Name Slicer_Salesperson: #N/A

Sheet Data
A1: Order ID | B1: Date | C1: Customer Name | D1: Region | E1: Product Category | F1: Product Name | G1: Quantity | H1: Unit Price | I1: Total Sales | J1: Payment Mode | K1: Salesperson
A2: ORD0001 | B2: 2024-07-08 | C2: Customer 1 | D2: West | E2: Furniture | F2: Bed | G2: 15 | H2: 884 | I2: 13260 | J2: Credit Card | K2: Vibek
A3: ORD0002 | B3: 2024-09-29 | C3: Customer 2 | D3: North | E3: Furniture | F3: Table | G3: 11 | H3: 558 | I3: 6138 | J3: Credit Card | K3: John
A4: ORD0003 | B4: 2024-07-30 | C4: Customer 3 | D4: West | E4: Groceries | F4: Eggs | G4: 11 | H4: 1623 | I4: 17853 | J4: Debit Card | K4: John
A5: ORD0004 | B5: 2024-07-31 | C5: Customer 4 | D5: West | E5: Clothing | F5: Shirt | G5: 4 | H5: 1818 | I5: 7272 | J5: UPI | K5: Vibek
A6: ORD0005 | B6: 2024-04-19 | C6: Customer 5 | D6: South | E6: Groceries | F6: Rice | G6: 13 | H6: 126 | I6: 1638 | J6: UPI | K6: Rahul
A7: ORD0006 | B7: 2024-07-05 | C7: Customer 6 | D7: East | E7: Clothing | F7: Jeans | G7: 4 | H7: 492 | I7: 1968 | J7: UPI | K7: Nisha
A8: ORD0007 | B8: 2024-03-18 | C8: Customer 7 | D8: West | E8: Groceries | F8: Milk | G8: 9 | H8: 1418 | I8: 12762 | J8: Debit Card | K8: Amit
A9: ORD0008 | B9: 2024-01-17 | C9: Customer 8 | D9: East | E9: Electronics | F9: Laptop | G9: 14 | H9: 1228 | I9: 17192 | J9: Credit Card | K9: Nisha
A10: ORD0009 | B10: 2024-06-19 | C10: Customer 9 | D10: West | E10: Furniture | F10: Table | G10: 12 | H10: 1497 | I10: 17964 | J10: Cash | K10: John
A11: ORD0010 | B11: 2024-09-27 | C11: Customer 10 | D11: West | E11: Furniture | F11: Chair | G11: 3 | H11: 1483 | I11: 4449 | J11: Cash | K11: Rahul
A12: ORD0011 | B12: 2024-09-12 | C12: Customer 11 | D12: East | E12: Groceries | F12: Rice | G12: 7 | H12: 1701 | I12: 11907 | J12: Credit Card | K12: Sneha
A13: ORD0012 | B13: 2024-01-19 | C13: Customer 12 | D13: West | E13: Clothing | F13: Jeans | G13: 1 | H13: 436 | I13: 436 | J13: Cash | K13: Amit
... A501: ORD0500 | B501: 2024-09-14 | C501: Customer 500 | D501: West | E501: Clothing | F501: Shirt | G501: 17 | H501: 472 | I501: 8024 | J501: Cash | K501: Nisha

Sheet Function
A1: Vlookup
A2: Q1. Find the Unit Price of the product in Order ID = “ORD0025”.
A3: Order ID | B3: Unit Price
A4: ORD0025 | B4: =VLOOKUP(A4,Data!A2:K501,8,0) -> 291
A6: Q2. Retrieve the Customer Name for Order ID “ORD0150”.
A7: Order ID | B7: Customer Name
A8: ORD0150 | B8: =VLOOKUP(A8,Data!A2:K501,3,0) -> Customer 150
A10: Q3. Find the Region for a given Order ID (in cell B2).
A11: Order ID | B11: Region
A12: ORD0001 | B12: =VLOOKUP(A12,Data!A2:H501,4,0) -> West
A14: HLOOKUP
A15: Q4. Use HLOOKUP to return the column header “Product Category” from row 1 of the Data sheet.
A16: Product Category | B16: =HLOOKUP(A16,Data!A1:K1,1,0) -> Product Category
A18: Q5. Get the “Payment Mode” from a horizontal lookup (assuming row 1 is transposed).
A19: Payment mode | B19: =HLOOKUP(A19,Data!A1:K1,1,0) -> Payment Mode
A21: Find Total Sales of all orders.
A22: Function used: SUM
A23: Total Sales | B23: =SUM(A23,Data!I2:I501) -> 5500361
A25: Count total number of orders.
A26: Function: COUNT / COUNTA
A27: CountA: | B27: =COUNT(Data!A2:H501) -> 1000
A28: Count: | B28: =COUNT(Data!A2:K501) -> 1500
A30: Find the highest single sale.
A31: Function: MAX
A32: Sales | B32: =MAX(Data!I2:I501) -> 37400
A34: Calculate average order value.
A35: Function: AVERAGE
A36: Order value | B36: =AVERAGE(Data!I2:I501) -> 11000.722
A38: Count how many orders were paid using UPI.
A39: Function: COUNTIF
A40: UPI | B40: =COUNTIF(Data!J2:J501,A40) -> 130
A42: Return the Product Name for Order ID “ORD0100”.
A43: Functions: INDEX + MATCH
A44: Order ID | B44: Product Name
A45: ORDO100 | B45: =INDEX(Data!E2:E501,MATCH(Data!A2,Data!A2:A501,0)) -> Furniture
A47: SINGLE COMBINED QUESTION:
A48: “Using Order ID in cell A2, display:
A49: Customer Name | B49: =VLOOKUP(A2,Data!A2:K501,3,1) -> Customer 500
A50: Region | B50: =VLOOKUP(A2,Data!A2:K501,4,1) -> West
A51: Total Sales | B51: =VLOOKUP(A2,Data!A2:K501,9,1) -> 8024
...

Sheet Pivot Table
A2: Row Labels | B2: Sum of Total Sales | E2: Row Labels | F2: Sum of Total Sales | I2: Row Labels | J2: Sum of Total Sales | K2: Sum of Unit Price
A3: East | B3: 1348379 | E3: 2024-01-02 | F3: 46387 | I3: Cash | J3: 1375570 | K3: 127214
A4: North | B4: 1759806 | E4: 2024-02-09 | F4: 20966 | I4: Credit Card | J4: 1519135 | K4: 141720
A5: South | B5: 1238570 | E5: 2024-03-01 | F5: 3006 | I5: Debit Card | J5: 1292752 | K5: 117392
A6: West | B6: 1153606 | E6: 2024-05-01 | F6: 34663 | I6: UPI | J6: 1312904 | K6: 125725
A7: Grand Total | B7: 5500361 | E7: 2024-06-01 | F7: 1858 | I7: Grand Total | J7: 5500361 | K7: 512051
E8: 2024-07-01 | F8: 8055
E9: 2024-07-28 | F9: 20968
E10: 2024-08-01 | F10: 31828 | I10: Row Labels | J10: Sum of Unit Price
E11: 2024-09-01 | F11: 16970 | I11: East | J11: 117432
E12: 2024-10-01 | F12: 40902 | I12: Clothing | J12: 27203
E13: 2024-10-27 | F13: 38259 | I13: Electronics | J13: 23186
E14: Grand Total | F14: 263862 | I14: Furniture | J14: 33823
I15: Groceries | J15: 33220
I16: North | J16: 154506
I17: Clothing | J17: 29416
I18: Electronics | J18: 42552
I19: Furniture | J19: 37087
A20: Row Labels | B20: Sum of Total Sales | E20: Row Labels | F20: Sum of Total Sales | I20: Groceries | J20: 45451
A21: Clothing | B21: 1186491 | E21: Amit | F21: 859982 | I21: South | J21: 113397
A22: Electronics | B22: 1364890 | E22: John | F22: 818227 | I22: Clothing | J22: 19406
A23: Furniture | B23: 1348565 | E23: Nisha | F23: 692443 | I23: Electronics | J23: 32711
A24: Groceries | B24: 1600415 | E24: Priya | F24: 638241 | I24: Furniture | J24: 27552
A25: Grand Total | B25: 5500361 | E25: Rahul | F25: 900122 | I25: Groceries | J25: 33728
E26: Sneha | F26: 711013 | I26: West | J26: 126716
E27: Vibek | F27: 880333 | I27: Clothing | J27: 30052
E28: Grand Total | F28: 5500361 | I28: Electronics | J28: 25968
I29: Furniture | J29: 32228
I30: Groceries | J30: 38468
I31: Grand Total | J31: 512051

Sheet Dashboard
B1: TOTAL SALES | D1: TOTAL ORDERS | F1: AVEARGE ORDER VALUE | J1: TOP SALESPERSON
B2: =SUM(Data!I1:I501) -> 5500361 | D2: =COUNTA(Data!A2:A501) -> 500 | F2: =AVERAGE(Data!I1:I501) -> 11000.722 | J2: =INDEX(Data!K2:K501,MATCH(MAX(Data!I2:I501),Data!I2:I501,0)) -> Rahul
